Workbook

Sheet อ่านก่อน
A1: ระบบจอง 4 ธุรกิจ · ไฟล์ตั้งค่าข้อมูลและโครงสร้างฐานข้อมูล
A3: ใช้ทำอะไร
A4: 1. ตั้งค่าร้าน: กรอกแท็บสีเขียว เหมือนตั้งค่าในระบบ Google Sheet เดิม
A5: 2. ลองระบบ: แท็บสีฟ้า (ลูกค้า) และสีส้ม (การจองและเงิน) มีข้อมูลสมมติ ตรงกับจอโปรโตไทป์ วันที่ 21 พ.ย. 2569
A6: 3. Import ลงฐานข้อมูล: แต่ละแท็บ = 1 ตาราง · แถว 2 คือชื่อคอลัมน์ในฐานข้อมูล · ข้อมูลเริ่มแถว 3
A7: สีแท็บและหัวตาราง = กลุ่มของข้อมูล
A8: ตั้งค่าร้าน · ร้านกรอกครั้งแรก แก้ได้เรื่อย ๆ: ธุรกิจ ห้อง บ้าน บริการ ราคา รอบ พนักงาน วันปิด
A9: ข้อมูลลูกค้า · ลูกค้า น้อง และวัคซีน · ของจริงเกิดเมื่อลูกค้าใช้งาน (ไฟล์นี้ใส่ข้อมูลสมมติ)
A10: การจองและเงิน · รายการที่เกิดทุกวัน (transaction): ทริป การจอง การชำระเงิน · ไฟล์นี้ใส่ข้อมูลสมมติ
A11: ระบบ · ระบบเขียนเอง ไม่ต้องกรอก ไม่ต้อง import
A12: เฟส 2 · ยังไม่รวมในใบเสนอราคา เตรียมโครงไว้ก่อน
A13: คอลัมน์ที่ขึ้นต้นด้วย ⚙ = ระบบเติมเอง (ในไฟล์นี้ใส่ค่าทดลองไว้) · คอลัมน์อื่นร้านกรอก/แก้ได้ · * = บังคับกรอก
... A23: ราคาและข้อมูลห้อง/บ้านเป็นข้อมูลตัวอย่างจากจอโปรโตไทป์ ร้านต้องแก้เป็นของจริงก่อนเปิดใช้ · ชื่อลูกค้าและเบอร์เป็นข้อมูลสมมติ

Sheet สารบัญ
A1: ลำดับ | B1: แท็บ | C1: ตาราง (db) | D1: กลุ่ม | E1: ใช้ทำอะไร | F1: จำนวนแถวตัวอย่าง
A2: 1 | B2: ตั้งค่าร้าน | C2: settings | D2: ตั้งค่าร้าน | E2: ค่าทั่วไปของร้าน (1 แถวต่อ 1 ค่า) · ห้ามใส่ token หรือรหัสลับ | F2: =MAX(0,COUNTA(ตั้งค่าร้าน!A:A)-2) -> 9
A3: 2 | B3: ธุรกิจ | C3: businesses | D3: ตั้งค่าร้าน | E3: 4 ธุรกิจ · ชนิดการจองกำหนดว่าระบบคิดที่ว่างแบบไหน | F3: =MAX(0,COUNTA(ธุรกิจ!A:A)-2) -> 4
A4: 3 | B4: ห้องและบ้าน | C4: units | D4: ตั้งค่าร้าน | E4: สิ่งที่จองได้ของธุรกิจแบบช่วงวันและรอบ: ห้อง Pet hotel · หลัง Villa · สระ | F4: =MAX(0,COUNTA(ห้องและบ้าน!A:A)-2) -> 7
A5: 4 | B5: รูป | C5: unit_photos | D5: ตั้งค่าร้าน | E5: รูปของห้อง บ้าน บริการ (หลายรูปต่อรายการ) · อัปโหลดผ่านหลังบ้าน หรือใส่ชื่อไฟล์ตอน import | F5: =MAX(0,COUNTA(รูป!A:A)-2) -> 8
A6: 5 | B6: ขนาดน้อง | C6: weight_tiers | D6: ตั้งค่าร้าน | E6: ช่วงน้ำหนักที่ใช้คิดราคา Grooming และแบ่งรอบสระ | F6: =MAX(0,COUNTA(ขนาดน้อง!A:A)-2) -> 4
A7: 6 | B7: บริการ | C7: services | D7: ตั้งค่าร้าน | E7: บริการ Grooming (หลัก/เสริม) และบริการเสริมของธุรกิจอื่น | F7: =MAX(0,COUNTA(บริการ!A:A)-2) -> 9
A8: 7 | B8: ราคาตามขนาด | C8: service_prices | D8: ตั้งค่าร้าน | E8: ราคาและเวลาของบริการแบบคิดตามขนาดน้อง (ราคาตัวอย่าง ร้านแก้ได้) | F8: =MAX(0,COUNTA(ราคาตามขนาด!A:A)-2) -> 16
A9: 8 | B9: รอบสระ | C9: pool_sessions | D9: ตั้งค่าร้าน | E9: รอบว่ายน้ำประจำ แบ่งตามขนาดน้อง | F9: =MAX(0,COUNTA(รอบสระ!A:A)-2) -> 3
A10: 9 | B10: พนักงาน | C10: staff | D10: ตั้งค่าร้าน | E10: พนักงานและช่าง · เข้าหลังบ้านด้วย LINE ผ่านลิงก์เชิญ (ไม่มีรหัสผ่าน) | F10: =MAX(0,COUNTA(พนักงาน!A:A)-2) -> 3
A11: 10 | B11: วันปิด | C11: closures | D11: ตั้งค่าร้าน | E11: ปิดทั้งธุรกิจ หรือปิดเฉพาะห้อง/บ้าน/รอบ ในช่วงวันที่กำหนด | F11: =MAX(0,COUNTA(วันปิด!A:A)-2) -> 2
A12: 11 | B12: ขายข้ามธุรกิจ | C12: cross_sells | D12: ตั้งค่าร้าน | E12: การ์ด "เพิ่มให้ทริปนี้ · จ่ายรวม QR เดียว" ที่ขึ้นก่อนชำระเงิน | F12: =MAX(0,COUNTA(ขายข้ามธุรกิจ!A:A)-2) -> 6
A13: 12 | B13: ลูกค้า | C13: customers | D13: ข้อมูลลูกค้า | E13: ลูกค้า (ข้อมูลสมมติ) · ของจริงระบบสร้างเมื่อลูกค้าเปิดหน้าจองใน LINE | F13: =MAX(0,COUNTA(ลูกค้า!A:A)-2) -> 7
A14: 13 | B14: น้อง | C14: pets | D14: ข้อมูลลูกค้า | E14: น้องของลูกค้า · ใช้ร่วมทุกธุรกิจ (ขนาดคิดจากน้ำหนักอัตโนมัติ) | F14: =MAX(0,COUNTA(น้อง!A:A)-2) -> 8
A15: 14 | B15: วัคซีน | C15: pet_vaccines | D15: ข้อมูลลูกค้า | E15: หลักฐานวัคซีน · พนักงานตรวจก่อนน้องจองสระ/Pet hotel ได้ | F15: =MAX(0,COUNTA(วัคซีน!A:A)-2) -> 7
A16: 15 | B16: ทริป | C16: orders | D16: การจองและเงิน | E16: 1 ทริป = การจองหลายรายการที่จ่ายรวม QR เดียว (มัดจำผูกกับทริป) | F16: =MAX(0,COUNTA(ทริป!A:A)-2) -> 6
A17: 16 | B17: การจอง | C17: bookings | D17: การจองและเงิน | E17: รายการจองทุกธุรกิจในตารางเดียว | F17: =MAX(0,COUNTA(การจอง!A:A)-2) -> 6
A18: 17 | B18: การชำระเงิน | C18: payments | D18: การจองและเงิน | E18: สลิปที่ลูกค้าแนบ · พนักงานกดผ่าน/ไม่พบเงิน | F18: =MAX(0,COUNTA(การชำระเงิน!A:A)-2) -> 2
A19: 18 | B19: การแจ้งเตือน | C19: notifications | D19: ระบบ | E19: คิวการแจ้งเตือนทุกช่องทาง (ระบบเขียนเอง ไม่ต้องกรอก ไม่ต้อง import) | F19: =MAX(0,COUNTA(การแจ้งเตือน!A:A)-2) -> 0
A20: 19 | B20: บัตรสระ | C20: passes | D20: เฟส 2 | E20: บัตรสระหลายครั้ง (อัปเกรดภายหลัง ยังไม่รวมในใบเสนอราคา) | F20: =MAX(0,COUNTA(บัตรสระ!A:A)-2) -> 1
A21: 20 | B21: โค้ดส่วนลด | C21: coupons | D21: เฟส 2 | E21: โค้ดส่วนลด (อัปเกรดภายหลัง ยังไม่รวมในใบเสนอราคา) | F21: =MAX(0,COUNTA(โค้ดส่วนลด!A:A)-2) -> 1

Sheet พจนานุกรม
A1: แท็บ | B1: ตาราง | C1: คอลัมน์ (db) | D1: ชื่อไทย | E1: ชนิด | F1: บังคับ | G1: ใครกรอก | H1: ตัวเลือก / อ้างอิง | I1: คำอธิบาย
A2: ตั้งค่าร้าน | B2: settings | C2: key | D2: หัวข้อ | E2: ข้อความ | F2: ✓ | G2: ร้าน | I2: ชื่อค่าที่ระบบใช้ (ห้ามเปลี่ยน)
A3: ตั้งค่าร้าน | B3: settings | C3: value | D3: ค่า | E3: ข้อความ | F3: ✓ | G3: ร้าน | I3: ค่าที่ร้านตั้ง
A4: ตั้งค่าร้าน | B4: settings | C4: note | D4: คำอธิบาย | E4: ข้อความ | G4: ร้าน | I4: ไว้อ่านเอง ระบบไม่ใช้
A5: ธุรกิจ | B5: businesses | C5: code | D5: รหัส | E5: ข้อความ | F5: ✓ | G5: ร้าน | I5: รหัสภาษาอังกฤษ ห้ามซ้ำ ห้ามเปลี่ยนหลังใช้งาน
A6: ธุรกิจ | B6: businesses | C6: name | D6: ชื่อ | E6: ข้อความ | F6: ✓ | G6: ร้าน | I6: ชื่อที่ลูกค้าเห็น
A7: ธุรกิจ | B7: businesses | C7: tagline | D7: คำบอกว่าเป็นของใคร | E7: ข้อความ | F7: ✓ | G7: ร้าน | I7: กันสับสน เช่น ที่พักสำหรับคน
A8: ธุรกิจ | B8: businesses | C8: booking_type | D8: ชนิดการจอง | E8: ตัวเลือก | F8: ✓ | G8: ร้าน | H8: stay,session,slot | I8: stay = ช่วงวัน · session = รอบ · slot = ช่องเวลาตามช่าง
A9: ธุรกิจ | B9: businesses | C9: color | D9: สีประจำ | E9: ข้อความ | G9: ร้าน | I9: รหัสสี เช่น #E8474C ใช้ในเมนู การ์ด ปฏิทิน
A10: ธุรกิจ | B10: businesses | C10: id_prefix | D10: ตัวนำรหัสจอง | E10: ข้อความ | F10: ✓ | G10: ร้าน | I10: เช่น H → H-261121-01
A11: ธุรกิจ | B11: businesses | C11: deposit_type | D11: แบบมัดจำ | E11: ตัวเลือก | F11: ✓ | G11: ร้าน | H11: full,percent,fixed | I11: full = จ่ายเต็ม · percent = % · fixed = บาทคงที่
A12: ธุรกิจ | B12: businesses | C12: deposit_value | D12: ค่ามัดจำ | E12: ตัวเลข | G12: ร้าน | I12: percent ใส่ 50 · fixed ใส่ 200
A13: ธุรกิจ | B13: businesses | C13: checkin_time | D13: เวลาเช็กอิน | E13: ข้อความ | G13: ร้าน | I13: เฉพาะ stay เช่น 14:00-18:00
A14: ธุรกิจ | B14: businesses | C14: checkout_time | D14: เวลาเช็กเอาต์ | E14: ข้อความ | G14: ร้าน | I14: เฉพาะ stay
A15: ธุรกิจ | B15: businesses | C15: cancel_policy | D15: เงื่อนไขยกเลิก (สรุป) | E15: ข้อความ | F15: ✓ | G15: ร้าน | I15: แสดงก่อนจ่าย ลูกค้าต้องติ๊กยอมรับ
A16: ธุรกิจ | B16: businesses | C16: need_vaccine | D16: ต้องมีวัคซีน | E16: ใช่/ไม่ใช่ | G16: ร้าน | H16: TRUE,FALSE | I16: TRUE = น้องที่ยังไม่ผ่านตรวจวัคซีนจองไม่ได้
A17: ธุรกิจ | B17: businesses | C17: calendar_id | D17: ปฏิทิน Google | E17: ข้อความ | G17: ระบบ | I17: ระบบเติมตอนเชื่อมปฏิทิน
A18: ธุรกิจ | B18: businesses | C18: sort | D18: ลำดับ | E18: ตัวเลข | G18: ร้าน | I18: ลำดับในหน้าแรก
A19: ธุรกิจ | B19: businesses | C19: active | D19: เปิดใช้ | E19: ใช่/ไม่ใช่ | F19: ✓ | G19: ร้าน | H19: TRUE,FALSE
A20: ธุรกิจ | B20: businesses | C20: open_hours | D20: เวลาเปิด | E20: ข้อความ | G20: ร้าน | I20: แสดงผล เช่น 09:00-18:00
A21: ธุรกิจ | B21: businesses | C21: closed_weekdays | D21: ปิดประจำทุก | E21: หลายค่า (คั่น ,) | G21: ร้าน | I21: วันคั่นด้วย , เช่น จ
A22: ธุรกิจ | B22: businesses | C22: cancel_rules | D22: ขั้นคืนเงิน | E22: ข้อความ | G22: ร้าน | I22: วันก่อนใช้บริการ:คืน% เช่น 7:100,3:50 (น้อยกว่านั้นไม่คืน)
A23: ห้องและบ้าน | B23: units | C23: code | D23: รหัส | E23: ข้อความ | F23: ✓ | G23: ร้าน | I23: ห้ามซ้ำ
A24: ห้องและบ้าน | B24: units | C24: business_code | D24: ธุรกิจ | E24: อ้างอิงตาราง | F24: ✓ | G24: ร้าน | H24: businesses.code
A25: ห้องและบ้าน | B25: units | C25: name | D25: ชื่อ | E25: ข้อความ | F25: ✓ | G25: ร้าน
A26: ห้องและบ้าน | B26: units | C26: summary | D26: คำอธิบายสั้น | E26: ข้อความ | G26: ร้าน | I26: บรรทัดใต้ชื่อในหน้าจอง
A27: ห้องและบ้าน | B27: units | C27: price | D27: ราคาปกติ (บาท) | E27: ตัวเลข | F27: ✓ | G27: ร้าน | I27: Pet hotel/Villa = ต่อคืน · สระ = ต่อตัวต่อรอบ (ตั้งในรอบสระได้)
A28: ห้องและบ้าน | B28: units | C28: weekend_price | D28: ราคาศุกร์–เสาร์ (บาท) | E28: ตัวเลข | G28: ร้าน | I28: ว่าง = ใช้ราคาปกติ
A29: ห้องและบ้าน | B29: units | C29: max_people | D29: รับคนสูงสุด | E29: ตัวเลข | G29: ร้าน | I29: Villa
A30: ห้องและบ้าน | B30: units | C30: bedrooms | D30: ห้องนอน | E30: ตัวเลข | G30: ร้าน | I30: Villa
A31: ห้องและบ้าน | B31: units | C31: max_pets | D31: รับน้องสูงสุด | E31: ตัวเลข | G31: ร้าน | I31: Pet hotel = ตัวต่อห้อง · Villa = พาน้องมาได้กี่ตัว
A32: ห้องและบ้าน | B32: units | C32: max_pet_kg | D32: น้ำหนักน้องสูงสุด (กก.) | E32: ตัวเลข | G32: ร้าน | I32: ว่าง = ไม่จำกัด
A33: ห้องและบ้าน | B33: units | C33: pet_fee | D33: ค่าน้องต่อตัวต่อคืน (บาท) | E33: ตัวเลข | G33: ร้าน | I33: Villa ที่พาน้องมาได้
A34: ห้องและบ้าน | B34: units | C34: amenities | D34: สิ่งอำนวยความสะดวก | E34: หลายค่า (คั่น ,) | G34: ร้าน | I34: คั่นด้วย ,
A35: ห้องและบ้าน | B35: units | C35: rules | D35: กฎ | E35: ข้อความ | G35: ร้าน | I35: กฎบ้าน / ข้อปฏิบัติ
A36: ห้องและบ้าน | B36: units | C36: sort | D36: ลำดับ | E36: ตัวเลข | G36: ร้าน
A37: ห้องและบ้าน | B37: units | C37: active | D37: เปิดจอง | E37: ใช่/ไม่ใช่ | F37: ✓ | G37: ร้าน | H37: TRUE,FALSE | I37: FALSE = ปิดห้อง (ซ่อม/ไม่ว่าง)
A38: รูป | B38: unit_photos | C38: owner_code | D38: ของรายการ | E38: ข้อความ | F38: ✓ | G38: ร้าน | I38: รหัสห้อง/บ้าน (units.code) หรือรหัสบริการ (services.code)
A39: รูป | B39: unit_photos | C39: file | D39: ไฟล์รูป | E39: ข้อความ | F39: ✓ | G39: ร้าน | I39: ชื่อไฟล์ในโฟลเดอร์รูป หรือ URL
A40: รูป | B40: unit_photos | C40: caption | D40: คำบรรยาย | E40: ข้อความ | G40: ร้าน
...

Sheet ตั้งค่าร้าน
A1: หัวข้อ * | B1: ค่า * | C1: คำอธิบาย | E1: กลุ่ม: ตั้งค่าร้าน
A2: key | B2: value | C2: note | E2: ค่าทั่วไปของร้าน (1 แถวต่อ 1 ค่า) · ห้ามใส่ token หรือรหัสลับ
A3: shop_name | B3: เพื่อนหมา PET LOVER | C3: ชื่อที่ขึ้นในหน้าจองและการ์ด LINE
A4: legal_name | B4: บริษัท พันธุ์พฤทธิ์ จำกัด | C4: ชื่อในใบเสร็จ (ทุกธุรกิจใช้นามเดียวกัน)
A5: promptpay_id | B5: (ใส่เลขพร้อมเพย์ของร้าน) | C5: ใช้สร้าง QR มัดจำ
A6: account_name | B6: (ชื่อบัญชีรับเงิน) | C6: แสดงใต้ QR ให้ลูกค้าเทียบก่อนโอน
A7: hold_minutes | B7: 30 | C7: กันที่ไว้กี่นาทีหลังกดจอง ไม่แนบสลิป = ปล่อยที่
A8: remind_hours_before | B8: 24 | C8: เตือนก่อนถึงวันกี่ชั่วโมง
A9: notify_email | B9: shop@example.com | C9: อีเมลกลางรับแจ้งจองใหม่ / สลิปรอตรวจ
A10: timezone | B10: Asia/Bangkok | C10: เขตเวลา
A11: policy_version | B11: 2026-11-01 | C11: เปลี่ยนเมื่อแก้นโยบาย ลูกค้าต้องกดยอมรับใหม่

Sheet ธุรกิจ
A1: รหัส * | B1: ชื่อ * | C1: คำบอกว่าเป็นของใคร * | D1: ชนิดการจอง * | E1: สีประจำ | F1: ตัวนำรหัสจอง * | G1: แบบมัดจำ * | H1: ค่ามัดจำ | I1: เวลาเช็กอิน | J1: เวลาเช็กเอาต์ | K1: เงื่อนไขยกเลิก (สรุป) * | L1: ต้องมีวัคซีน | M1: ⚙ ปฏิทิน Google | N1: ลำดับ | O1: เปิดใช้ * | P1: เวลาเปิด | Q1: ปิดประจำทุก | R1: ขั้นคืนเงิน | T1: กลุ่ม: ตั้งค่าร้าน
A2: code | B2: name | C2: tagline | D2: booking_type | E2: color | F2: id_prefix | G2: deposit_type | H2: deposit_value | I2: checkin_time | J2: checkout_time | K2: cancel_policy | L2: need_vaccine | M2: calendar_id | N2: sort | O2: active | P2: open_hours | Q2: closed_weekdays | R2: cancel_rules | T2: 4 ธุรกิจ · ชนิดการจองกำหนดว่าระบบคิดที่ว่างแบบไหน
A3: pet_hotel | B3: Pet hotel | C3: ฝากน้องค้างคืน | D3: stay | E3: #FDF5DC | F3: H | G3: full | I3: 14:00-18:00 | J3: 12:00 | K3: ยกเลิกก่อน 3 วัน คืนเป็นเครดิต · น้อยกว่า 3 วันไม่คืน | L3: =TRUE() -> TRUE | N3: 1 | O3: =TRUE() -> TRUE | P3: 14:00-18:00 | R3: 3:100
A4: villa | B4: Villa | C4: ที่พักสำหรับคน | D4: stay | E4: #111111 | F4: V | G4: percent | H4: 50 | I4: 14:00 | J4: 12:00 | K4: ยกเลิกก่อน 14 วัน คืนเครดิตเต็ม · 7–13 วัน เครดิต 50% · น้อยกว่า 7 วันไม่คืน | L4: =FALSE() -> FALSE | N4: 2 | O4: =TRUE() -> TRUE | P4: เข้า 14:00 · ออก 12:00 | R4: 14:100,7:50
A5: pool | B5: สระ | C5: จองรอบว่ายน้ำ | D5: session | E5: #8FC9F0 | F5: P | G5: full | K5: ยกเลิกก่อน 2 ชม. คืนสิทธิ์ · หลังจากนั้นไม่คืน | L5: =TRUE() -> TRUE | N5: 3 | O5: =TRUE() -> TRUE | P5: 09:00-18:00 | R5: 1:100
A6: grooming | B6: Grooming | C6: อาบน้ำ ตัดขน | D6: slot | E6: #E8444C | F6: G | G6: fixed | H6: 200 | K6: ยกเลิก/เลื่อนก่อน 24 ชม. ฟรี · น้อยกว่า 24 ชม. ไม่คืนมัดจำ | L6: =FALSE() -> FALSE | N6: 4 | O6: =TRUE() -> TRUE | P6: 09:00-18:00 | Q6: จ | R6: 1:100

Sheet ห้องและบ้าน
A1: รหัส * | B1: ธุรกิจ * | C1: ชื่อ * | D1: คำอธิบายสั้น | E1: ราคาปกติ (บาท) * | F1: ราคาศุกร์–เสาร์ (บาท) | G1: รับคนสูงสุด | H1: ห้องนอน | I1: รับน้องสูงสุด | J1: น้ำหนักน้องสูงสุด (กก.) | K1: ค่าน้องต่อตัวต่อคืน (บาท) | L1: สิ่งอำนวยความสะดวก | M1: กฎ | N1: ลำดับ | O1: เปิดจอง * | Q1: กลุ่ม: ตั้งค่าร้าน
A2: code | B2: business_code | C2: name | D2: summary | E2: price | F2: weekend_price | G2: max_people | H2: bedrooms | I2: max_pets | J2: max_pet_kg | K2: pet_fee | L2: amenities | M2: rules | N2: sort | O2: active | Q2: สิ่งที่จองได้ของธุรกิจแบบช่วงวันและรอบ: ห้อง Pet hotel · หลัง Villa · สระ
A3: COZY1 | B3: pet_hotel | C3: Cozy 1 | D3: 6 ตร.ม. · รับ 1 ตัว | E3: 650 | I3: 1 | J3: 10 | L3: แอร์, กล้องดูน้อง | N3: 1 | O3: =TRUE() -> TRUE
A4: COZY2 | B4: pet_hotel | C4: Cozy 2 | D4: 6 ตร.ม. · รับ 1 ตัว | E4: 650 | I4: 1 | J4: 10 | L4: แอร์, กล้องดูน้อง | N4: 2 | O4: =TRUE() -> TRUE
A5: GARDEN1 | B5: pet_hotel | C5: Garden 1 | D5: ติดสนาม · รับ 2 ตัว | E5: 950 | I5: 2 | L5: แอร์, สนามส่วนตัว | N5: 3 | O5: =TRUE() -> TRUE
A6: GARDEN2 | B6: pet_hotel | C6: Garden 2 | D6: ติดสนาม · รับ 2 ตัว | E6: 950 | I6: 2 | L6: แอร์, สนามส่วนตัว | N6: 4 | O6: =TRUE() -> TRUE
A7: TEAK | B7: villa | C7: บ้านสักริมสวน | D7: 3 ห้องนอน · 8 คน · สระส่วนตัว | E7: 4500 | G7: 8 | H7: 3 | I7: 2 | K7: 300 | L7: สระส่วนตัว, ครัว, Wi-Fi, ที่จอดรถ | M7: ห้ามสูบบุหรี่ในบ้าน · งดเสียงดังหลัง 22:00 | N7: 1 | O7: =TRUE() -> TRUE
A8: LOFT | B8: villa | C8: ลอฟต์ทุ่งนา | D8: 2 ห้องนอน · 4 คน | E8: 3200 | G8: 4 | H8: 2 | I8: 2 | K8: 300 | L8: ครัว, Wi-Fi, ระเบียงวิวนา | M8: ห้ามสูบบุหรี่ในบ้าน | N8: 2 | O8: =TRUE() -> TRUE
A9: POOL1 | B9: pool | C9: สระหลัก | D9: สระน้ำเกลือสำหรับน้อง | E9: 240 | L9: ห้องอาบน้ำ, ผ้าเช็ดตัว | M9: น้องต้องมีวัคซีนครบ · เจ้าของอยู่ดูแลตลอด | N9: 1 | O9: =TRUE() -> TRUE

Sheet รูป
A1: ของรายการ * | B1: ไฟล์รูป * | C1: คำบรรยาย | D1: รูปปก | E1: ลำดับ | G1: กลุ่ม: ตั้งค่าร้าน
A2: owner_code | B2: file | C2: caption | D2: is_cover | E2: sort | G2: รูปของห้อง บ้าน บริการ (หลายรูปต่อรายการ) · อัปโหลดผ่านหลังบ้าน หรือใส่ชื่อไฟล์ตอน import
A3: TEAK | B3: teak-01.jpg | C3: ด้านหน้าบ้าน | D3: =TRUE() -> TRUE | E3: 1
A4: TEAK | B4: teak-02.jpg | C4: สระส่วนตัว | D4: =FALSE() -> FALSE | E4: 2
A5: TEAK | B5: teak-03.jpg | C5: ห้องนอนใหญ่ | D5: =FALSE() -> FALSE | E5: 3
A6: LOFT | B6: loft-01.jpg | C6: วิวทุ่งนา | D6: =TRUE() -> TRUE | E6: 1
A7: COZY1 | B7: cozy-01.jpg | D7: =TRUE() -> TRUE | E7: 1
A8: GARDEN1 | B8: garden-01.jpg | C8: สนามหน้าห้อง | D8: =TRUE() -> TRUE | E8: 1
A9: POOL1 | B9: pool-01.jpg | D9: =TRUE() -> TRUE | E9: 1
A10: G-BATH | B10: g-bath.jpg | D10: =TRUE() -> TRUE | E10: 1

Sheet ขนาดน้อง
A1: รหัส * | B1: ชื่อ * | C1: มากกว่า (กก.) * | D1: ไม่เกิน (กก.) | F1: กลุ่ม: ตั้งค่าร้าน
A2: code | B2: label | C2: min_kg | D2: max_kg | F2: ช่วงน้ำหนักที่ใช้คิดราคา Grooming และแบ่งรอบสระ
A3: S | B3: เล็ก | C3: 0 | D3: 5
A4: M | B4: กลาง | C4: 5 | D4: 10
A5: L | B5: ใหญ่ | C5: 10 | D5: 20
A6: XL | B6: ใหญ่พิเศษ | C6: 20

Sheet บริการ
A1: รหัส * | B1: ธุรกิจ * | C1: ชื่อ * | D1: ประเภท * | E1: คำอธิบาย | F1: คิดราคาแบบ * | G1: ราคา (บาท) | H1: ใช้เวลา (นาที) | I1: ลำดับ | J1: เปิดใช้ * | L1: กลุ่ม: ตั้งค่าร้าน
A2: code | B2: business_code | C2: name | D2: kind | E2: description | F2: price_mode | G2: price | H2: duration_min | I2: sort | J2: active | L2: บริการ Grooming (หลัก/เสริม) และบริการเสริมของธุรกิจอื่น
A3: G-BATH | B3: grooming | C3: อาบน้ำ + เป่า | D3: main | F3: by_weight | I3: 1 | J3: =TRUE() -> TRUE
A4: G-CUT | B4: grooming | C4: อาบ + ตัดทรง | D4: main | F4: by_weight | I4: 2 | J4: =TRUE() -> TRUE
A5: G-STYLE | B5: grooming | C5: แต่งทรงอย่างเดียว | D5: main | E5: ไม่อาบ · ขนต้องสะอาดและแห้ง | F5: by_weight | I5: 3 | J5: =TRUE() -> TRUE
A6: G-SPOT | B6: grooming | C6: ตัดเฉพาะจุด | D6: main | E6: หน้า เท้า ก้น | F6: flat | G6: 200 | H6: 30 | I6: 4 | J6: =TRUE() -> TRUE
A7: G-DRY | B7: grooming | C7: ไดขนทั้งตัว | D7: main | F7: by_weight | I7: 5 | J7: =TRUE() -> TRUE
A8: A-NAIL | B8: grooming | C8: ตัดเล็บ | D8: addon | F8: flat | G8: 80 | H8: 10 | I8: 10 | J8: =TRUE() -> TRUE
A9: A-TEETH | B9: grooming | C9: แปรงฟัน | D9: addon | F9: flat | G9: 100 | H9: 10 | I9: 11 | J9: =TRUE() -> TRUE
A10: A-EAR | B10: grooming | C10: เช็ดหู | D10: addon | F10: flat | G10: 60 | H10: 10 | I10: 12 | J10: =TRUE() -> TRUE
A11: A-SPA | B11: grooming | C11: สปาบำรุงขน | D11: addon | F11: flat | G11: 200 | H11: 20 | I11: 13 | J11: =TRUE() -> TRUE

Sheet ราคาตามขนาด
A1: บริการ * | B1: ขนาด * | C1: ราคา (บาท) * | D1: ใช้เวลา (นาที) * | F1: กลุ่ม: ตั้งค่าร้าน
A2: service_code | B2: tier_code | C2: price | D2: duration_min | F2: ราคาและเวลาของบริการแบบคิดตามขนาดน้อง (ราคาตัวอย่าง ร้านแก้ได้)
A3: G-BATH | B3: S | C3: 350 | D3: 60
A4: G-BATH | B4: M | C4: 450 | D4: 75
A5: G-BATH | B5: L | C5: 550 | D5: 90
A6: G-BATH | B6: XL | C6: 700 | D6: 120
A7: G-CUT | B7: S | C7: 550 | D7: 120
A8: G-CUT | B8: M | C8: 650 | D8: 135
A9: G-CUT | B9: L | C9: 750 | D9: 150
A10: G-CUT | B10: XL | C10: 900 | D10: 180
A11: G-STYLE | B11: S | C11: 300 | D11: 60
A12: G-STYLE | B12: M | C12: 400 | D12: 75
A13: G-STYLE | B13: L | C13: 500 | D13: 90
A14: G-STYLE | B14: XL | C14: 650 | D14: 120
... A18: G-DRY | B18: XL | C18: 800 | D18: 150

Sheet รอบสระ
A1: รหัส * | B1: สระ * | C1: วันที่เปิด * | D1: เริ่ม * | E1: จบ * | F1: ขนาดที่รับ * | G1: รับได้ (ตัว) * | H1: ราคาต่อตัว (บาท) * | I1: เปิด * | K1: กลุ่ม: ตั้งค่าร้าน
A2: code | B2: unit_code | C2: weekdays | D2: start | E2: end | F2: size_rule | G2: capacity | H2: price | I2: active | K2: รอบว่ายน้ำประจำ แบ่งตามขนาดน้อง
A3: S1000 | B3: POOL1 | C3: จ,อ,พ,พฤ,ศ,ส,อา | D3: 10:00 | E3: 11:00 | F3: small | G3: 10 | H3: 240 | I3: =TRUE() -> TRUE
A4: S1300 | B4: POOL1 | C4: จ,อ,พ,พฤ,ศ,ส,อา | D4: 13:00 | E4: 14:00 | F4: large | G4: 15 | H4: 240 | I4: =TRUE() -> TRUE
A5: S1500 | B5: POOL1 | C5: ส,อา | D5: 15:00 | E5: 16:00 | F5: all | G5: 8 | H5: 240 | I5: =TRUE() -> TRUE

Sheet พนักงาน
A1: รหัส * | B1: ชื่อเรียก * | C1: บทบาท * | D1: ดูแลธุรกิจ * | E1: เป็นช่าง Grooming | F1: วันทำงาน | G1: เริ่มงาน | H1: เลิกงาน | I1: ⚙ LINE userId | J1: ⚙ สถานะเชิญ | L1: กลุ่ม: ตั้งค่าร้าน
A2: code | B2: display_name | C2: role | D2: businesses | E2: is_groomer | F2: work_days | G2: work_start | H2: work_end | I2: line_user_id | J2: invite_status | L2: พนักงานและช่าง · เข้าหลังบ้านด้วย LINE ผ่านลิงก์เชิญ (ไม่มีรหัสผ่าน)
A3: ST01 | B3: ฝน | C3: owner | D3: all | E3: =FALSE() -> FALSE | J3: pending
A4: ST02 | B4: มะปราง | C4: staff | D4: grooming | E4: =TRUE() -> TRUE | F4: อ,พ,พฤ,ศ,ส,อา | G4: 10:00 | H4: 19:00 | J4: pending
A5: ST03 | B5: ต้นหอม | C5: staff | D5: grooming,pool | E5: =TRUE() -> TRUE | F5: จ,อ,พ,ศ,ส,อา | G5: 10:00 | H5: 19:00 | J5: pending

Sheet วันปิด
A1: ธุรกิจ * | B1: เฉพาะรายการ | C1: ตั้งแต่ * | D1: ถึง * | E1: เหตุผล | G1: กลุ่ม: ตั้งค่าร้าน
A2: business_code | B2: unit_code | C2: date_from | D2: date_to | E2: reason | G2: ปิดทั้งธุรกิจ หรือปิดเฉพาะห้อง/บ้าน/รอบ ในช่วงวันที่กำหนด
A3: pool | C3: 2026-11-25 | D3: 2026-11-25 | E3: ล้างระบบกรองน้ำ
A4: villa | B4: LOFT | C4: 2026-12-01 | D4: 2026-12-03 | E4: ซ่อมบำรุง

Sheet ขายข้ามธุรกิจ
A1: ขึ้นในหน้าจอง * | B1: เสนอธุรกิจ * | C1: รายการที่เสนอ | D1: หัวการ์ด * | E1: วันที่เสนอ * | F1: เงื่อนไข | G1: ลำดับ | H1: เปิดใช้ | J1: กลุ่ม: ตั้งค่าร้าน
A2: from_business | B2: offer_business | C2: offer_item | D2: title | E2: when_rule | F2: condition | G2: sort | H2: active | J2: การ์ด "เพิ่มให้ทริปนี้ · จ่ายรวม QR เดียว" ที่ขึ้นก่อนชำระเงิน
A3: pet_hotel | B3: grooming | C3: G-BATH | D3: อาบน้ำก่อนรับกลับ | E3: checkout_day | G3: 1
A4: pet_hotel | B4: pool | D4: ว่ายน้ำระหว่างพัก | E4: during_stay | G4: 2
A5: villa | B5: pet_hotel | D5: ฝากน้องที่ Pet hotel | E5: during_stay | G5: 1
A6: villa | B6: pool | D6: รอบสระระหว่างพัก | E6: during_stay | F6: เฉพาะเมื่อพาน้องมา | G6: 2
A7: villa | B7: grooming | C7: G-BATH | D7: อาบน้ำน้องก่อนกลับ | E7: checkout_day | F7: เฉพาะเมื่อพาน้องมา | G7: 3
A8: pool | B8: grooming | C8: G-BATH | D8: อาบน้ำหลังว่าย | E8: same_day | G8: 1

Sheet ลูกค้า
A1: รหัส * | B1: ⚙ LINE userId | C1: ชื่อเรียก * | D1: เบอร์ | E1: อีเมล | F1: ⚙ ยินยอม PDPA เมื่อ | G1: ⚙ ยอมรับนโยบายฉบับ | I1: กลุ่ม: ข้อมูลลูกค้า
A2: code | B2: line_user_id | C2: display_name | D2: phone | E2: email | F2: pdpa_at | G2: policy_version | I2: ลูกค้า (ข้อมูลสมมติ) · ของจริงระบบสร้างเมื่อลูกค้าเปิดหน้าจองใน LINE
A3: C001 | B3: Utest0001 | C3: มายด์ | D3: 0800000001 | E3: mind@example.com | F3: 2026-11-01 10:00 | G3: 2026-11-01
A4: C002 | B4: Utest0002 | C4: ต้า | D4: 0800000002 | F4: 2026-11-02 09:00 | G4: 2026-11-01
A5: C003 | B5: Utest0003 | C5: มิว | D5: 0800000003 | F5: 2026-11-03 12:00 | G5: 2026-11-01
A6: C004 | B6: Utest0004 | C6: ธาม | D6: 0800000004 | E6: tham@example.com | F6: 2026-11-05 20:00 | G6: 2026-11-01
A7: C005 | B7: Utest0005 | C7: จ๋า | D7: 0800000005 | F7: 2026-11-06 08:30 | G7: 2026-11-01
A8: C006 | B8: Utest0006 | C8: แพรว | D8: 0800000006 | F8: 2026-11-10 13:00 | G8: 2026-11-01
A9: C007 | B9: Utest0007 | C9: บีม | D9: 0800000007 | F9: 2026-11-12 18:00 | G9: 2026-11-01

Sheet น้อง
A1: รหัส * | B1: เจ้าของ * | C1: ชื่อน้อง * | D1: ชนิด * | E1: สายพันธุ์ | F1: น้ำหนัก (กก.) * | G1: ฝากบอกร้าน | H1: ข้อควรระวัง | J1: กลุ่ม: ข้อมูลลูกค้า
A2: code | B2: customer_code | C2: name | D2: species | E2: breed | F2: weight_kg | G2: note | H2: tags | J2: น้องของลูกค้า · ใช้ร่วมทุกธุรกิจ (ขนาดคิดจากน้ำหนักอัตโนมัติ)
A3: P001 | B3: C001 | C3: โมจิ | D3: dog | E3: ปอม | F3: 3.2 | H3: กลัวเสียงไดร์
A4: P002 | B4: C001 | C4: ข้าวตู | D4: dog | E4: ชิสุ | F4: 6.5 | H4: แพ้ไก่
A5: P003 | B5: C002 | C5: พุดดิ้ง | D5: dog | E5: ชิบะ | F5: 9 | H5: กลัวเสียงไดร์
A6: P004 | B6: C002 | C6: นมสด | D6: dog | E6: ชิบะ | F6: 8.5
A7: P005 | B7: C003 | C7: ลาเต้ | D7: dog | E7: พุดเดิ้ล | F7: 4.8
A8: P006 | B8: C005 | C8: ปุยฝ้าย | D8: dog | E8: ปอม | F8: 2.9
A9: P007 | B9: C007 | C9: ขนมปัง | D9: dog | E9: บีเกิ้ล | F9: 10.2 | H9: ชอบหนี
A10: P008 | B10: C006 | C10: ถั่วแดง | D10: dog | E10: พันธุ์ผสม | F10: 7

Sheet วัคซีน
A1: น้อง * | B1: วัคซีน * | C1: หมดอายุ * | D1: รูปสมุดวัคซีน | E1: ⚙ สถานะตรวจ * | F1: ⚙ ตรวจโดย | H1: กลุ่ม: ข้อมูลลูกค้า
A2: pet_code | B2: vaccine | C2: expires_on | D2: photo | E2: status | F2: reviewed_by | H2: หลักฐานวัคซีน · พนักงานตรวจก่อนน้องจองสระ/Pet hotel ได้
A3: P001 | B3: รวม 5 โรค | C3: 2027-06-30 | D3: p001-vac.jpg | E3: approved | F3: ST01
A4: P001 | B4: พิษสุนัขบ้า | C4: 2027-06-30 | D4: p001-vac.jpg | E4: approved | F4: ST01
A5: P002 | B5: รวม 5 โรค | C5: 2026-10-01 | D5: p002-vac.jpg | E5: approved | F5: ST01
A6: P003 | B6: รวม 5 โรค | C6: 2027-03-15 | D6: p003-vac.jpg | E6: approved | F6: ST01
A7: P004 | B7: รวม 5 โรค | C7: 2027-03-15 | D7: p004-vac.jpg | E7: approved | F7: ST01
A8: P006 | B8: รวม 5 โรค | C8: 2027-01-20 | D8: p006-vac.jpg | E8: approved | F8: ST01
A9: P007 | B9: รวม 5 โรค | C9: 2027-02-10 | D9: p007-vac.jpg | E9: approved | F9: ST01

Sheet ทริป
A1: ⚙ รหัสทริป * | B1: ⚙ ลูกค้า * | C1: ⚙ สถานะ * | D1: ⚙ ยอดทั้งหมด * | E1: ⚙ ต้องจ่ายตอนจอง * | F1: ⚙ กันที่ถึง | G1: ⚙ สร้างเมื่อ * | I1: กลุ่ม: การจองและเงิน
A2: code | B2: customer_code | C2: status | D2: total | E2: due_now | F2: hold_until | G2: created_at | I2: 1 ทริป = การจองหลายรายการที่จ่ายรวม QR เดียว (มัดจำผูกกับทริป)
A3: T-261120-01 | B3: C002 | C3: paid | D3: 480 | E3: 480 | G3: 2026-11-20 09:10
A4: T-261119-01 | B4: C003 | C4: paid | D4: 550 | E4: 200 | G4: 2026-11-19 21:00
A5: T-261115-01 | B5: C004 | C5: paid | D5: 3200 | E5: 1600 | G5: 2026-11-15 19:40
A6: T-261118-01 | B6: C005 | C6: paid | D6: 650 | E6: 650 | G6: 2026-11-18 12:00
A7: T-261121-01 | B7: C006 | C7: pending_review | D7: 9600 | E7: 4800 | F7: 2026-11-21 10:30 | G7: 2026-11-21 10:00
A8: T-261121-02 | B8: C007 | C8: pending_review | D8: 950 | E8: 950 | F8: 2026-11-21 10:45 | G8: 2026-11-21 10:15

Sheet การจอง
A1: ⚙ รหัสจอง * | B1: ⚙ ทริป * | C1: ⚙ ธุรกิจ * | D1: ⚙ ห้อง/บ้าน/รอบ | E1: ⚙ บริการ | F1: ⚙ ช่าง | G1: ⚙ เริ่ม * | H1: ⚙ จบ * | I1: ⚙ น้อง | J1: ⚙ ผู้เข้าพัก (คน) | K1: ⚙ ราคา * | L1: ⚙ สถานะ * | N1: กลุ่ม: การจองและเงิน
A2: code | B2: order_code | C2: business_code | D2: unit_code | E2: service_code | F2: staff_code | G2: start_at | H2: end_at | I2: pet_codes | J2: guests | K2: price | L2: status | N2: รายการจองทุกธุรกิจในตารางเดียว
A3: P-261121-01 | B3: T-261120-01 | C3: pool | D3: S1000 | G3: 2026-11-21 10:00 | H3: 2026-11-21 11:00 | I3: P003,P004 | K3: 480 | L3: confirmed
A4: G-261121-01 | B4: T-261119-01 | C4: grooming | E4: G-CUT | F4: ST02 | G4: 2026-11-21 14:00 | H4: 2026-11-21 16:00 | I4: P005 | K4: 550 | L4: confirmed
A5: V-261121-01 | B5: T-261115-01 | C5: villa | D5: LOFT | G5: 2026-11-21 14:00 | H5: 2026-11-22 12:00 | J5: 2 | K5: 3200 | L5: confirmed
A6: H-261121-01 | B6: T-261118-01 | C6: pet_hotel | D6: COZY1 | G6: 2026-11-21 16:00 | H6: 2026-11-22 12:00 | I6: P006 | K6: 650 | L6: confirmed
A7: V-261121-02 | B7: T-261121-01 | C7: villa | D7: TEAK | G7: 2026-11-21 14:00 | H7: 2026-11-23 12:00 | I7: P008 | J7: 6 | K7: 9600 | L7: holding
A8: H-261121-02 | B8: T-261121-02 | C8: pet_hotel | D8: GARDEN2 | G8: 2026-11-21 16:00 | H8: 2026-11-22 12:00 | I8: P007 | K8: 950 | L8: holding

Sheet การชำระเงิน
A1: ⚙ รหัส * | B1: ⚙ ทริป * | C1: ⚙ ยอดที่ควรได้ * | D1: ⚙ ยอดในสลิป | E1: ⚙ รูปสลิป * | F1: ⚙ สถานะ * | G1: ⚙ ตรวจโดย | H1: ⚙ แนบเมื่อ * | J1: กลุ่ม: การจองและเงิน
A2: code | B2: order_code | C2: amount_due | D2: amount_slip | E2: slip_file | F2: status | G2: reviewed_by | H2: created_at | J2: สลิปที่ลูกค้าแนบ · พนักงานกดผ่าน/ไม่พบเงิน
A3: PAY-0001 | B3: T-261121-01 | C3: 4800 | D3: 4500 | E3: slip-0001.jpg | F3: pending | H3: 2026-11-21 10:05
A4: PAY-0002 | B4: T-261121-02 | C4: 950 | D4: 950 | E4: slip-0002.jpg | F4: pending | H4: 2026-11-21 10:20

Sheet การแจ้งเตือน
A1: ⚙ รหัส * | B1: ⚙ การจอง | C1: ⚙ ช่องทาง * | D1: ⚙ แบบข้อความ * | E1: ⚙ สถานะ * | F1: ⚙ ส่งไปแล้วกี่ครั้ง | G1: ⚙ ส่งเมื่อ | I1: กลุ่ม: ระบบ
A2: id | B2: booking_code | C2: channel | D2: template | E2: status | F2: tries | G2: sent_at | I2: คิวการแจ้งเตือนทุกช่องทาง (ระบบเขียนเอง ไม่ต้องกรอก ไม่ต้อง import)

Sheet บัตรสระ
A1: ⚙ รหัส * | B1: ⚙ ลูกค้า * | C1: จำนวนครั้ง * | D1: ⚙ เหลือ * | E1: หมดอายุ * | G1: กลุ่ม: เฟส 2
A2: code | B2: customer_code | C2: total_uses | D2: remaining | E2: expires_on | G2: บัตรสระหลายครั้ง (อัปเกรดภายหลัง ยังไม่รวมในใบเสนอราคา)
A3: PS-0001 | B3: C002 | C3: 10 | D3: 6 | E3: 2027-02-28

Sheet โค้ดส่วนลด
A1: โค้ด * | B1: ใช้กับธุรกิจ | C1: แบบส่วนลด * | D1: ค่าส่วนลด * | E1: ใช้ได้ถึง | F1: ใช้ได้กี่ครั้ง | H1: กลุ่ม: เฟส 2
A2: code | B2: business_code | C2: discount_type | D2: discount_value | E2: valid_until | F2: max_uses | H2: โค้ดส่วนลด (อัปเกรดภายหลัง ยังไม่รวมในใบเสนอราคา)
A3: POOLFRIEND | B3: pool | C3: percent | D3: 20 | E3: 2026-12-31 | F3: 100
